2013-03-13 02:36:41,168:INFO: Error (<class '_mysql_exceptions.OperationalError'>) occurred in crawl.py, line 1124: (1045, "Access denied for user 'root'@'localhost' (using password: NO)")
2013-03-13 02:36:41,168:INFO: Traceback:
2013-03-13 02:36:41,171:INFO: Traceback (most recent call last):
  File "E:\installs\Git\storage\GroceryOTG\Server\src\com\groceryotg\crawler\crawl.py", line 1124, in <module>
    con = mdb.connect('localhost', mysql_user, mysql_password, mysql_db)
  File "E:\installs\Python27\lib\site-packages\MySQLdb\__init__.py", line 81, in Connect
    return Connection(*args, **kwargs)
  File "E:\installs\Python27\lib\site-packages\MySQLdb\connections.py", line 187, in __init__
    super(Connection, self).__init__(*args, **kwargs2)
OperationalError: (1045, "Access denied for user 'root'@'localhost' (using password: NO)")

